Workbook

Sheet LookupTables
A1: Country | B1: CountryFactor | D1: Month | E1: SeasonName | F1: SeasonFactor | H1: Parameter | I1: Value
A2: USA | B2: 1 | D2: 1 | E2: Winter | F2: 1.3 | H2: NoiseMean | I2: 0
A3: Canada | B3: 1.2 | D3: 2 | E3: Winter | F3: 1.25 | H3: NoiseStdDev | I3: 50
A4: UK | B4: 0.9 | D4: 3 | E4: Spring | F4: 0.8 | H4: WinterBaseCoeff | I4: 5
A5: Germany | B5: 1.1 | D5: 4 | E5: Spring | F5: 0.7 | H5: SummerBaseCoeff | I5: 5
A6: Australia | B6: 0.85 | D6: 5 | E6: Spring | F6: 0.75 | H6: InvBufferPct | I6: 0.1
A7: Japan | B7: 1.05 | D7: 6 | E7: Summer | F7: 1.2
A8: Brazil | B8: 0.7 | D8: 7 | E8: Summer | F8: 1.35
D9: 8 | E9: Summer | F9: 1.25
D10: 9 | E10: Fall | F10: 0.8
D11: 10 | E11: Fall | F11: 0.85
D12: 11 | E12: Fall | F12: 1
D13: 12 | E13: Winter | F13: 1.4

Sheet Data
A1: Date | B1: Country | C1: Temp_F | D1: Month | E1: Year | F1: CountryFactor | G1: SeasonFactor | H1: Noise | I1: Winter_Demand | J1: Summer_Demand | K1: Total_Demand | L1: Inventory | M1: Sales | N1: Lost_Sales | O1: Excess_Inventory
A2: 45292 | B2: USA | C2: 31.3 | D2: =MONTH(A2) -> 1 | E2: =YEAR(A2) -> 2024 | F2: =VLOOKUP(B2,LookupTables!$A$2:$B$8,2,FALSE) -> 1 | G2: =INDEX(LookupTables!$F$2:$F$13,MATCH(D2,LookupTables!$D$2:$D$13,0)) -> 1.3 | H2: =_xlfn.NORM.INV(RAND(),LookupTables!$I$2,LookupTables!$I$3) -> 23.726724 | I2: =MAX(0,(100-C2)*LookupTables!$I$4*F2*G2+H2) -> 470.27672 | J2: =MAX(0,(C2-50)*LookupTables!$I$5*F2*G2+H2) -> 0 | K2: =I2+J2 -> 470.27672 | L2: =MAX(0,K2*(1+_xlfn.NORM.INV(RAND(),LookupTables!$I$6,0.08))) -> 562.86673 | M2: =MIN(K2,L2) -> 470.27672 | N2: =MAX(0,K2-L2) -> 0 | O2: =MAX(0,L2-K2) -> 92.590005
A3: 45299 | B3: Canada | C3: 14.1 | D3: =MONTH(A3) -> 1 | E3: =YEAR(A3) -> 2024 | F3: =VLOOKUP(B3,LookupTables!$A$2:$B$8,2,FALSE) -> 1.2 | G3: =INDEX(LookupTables!$F$2:$F$13,MATCH(D3,LookupTables!$D$2:$D$13,0)) -> 1.3 | H3: =_xlfn.NORM.INV(RAND(),LookupTables!$I$2,LookupTables!$I$3) -> 29.253404 | I3: =MAX(0,(100-C3)*LookupTables!$I$4*F3*G3+H3) -> 699.2734 | J3: =MAX(0,(C3-50)*LookupTables!$I$5*F3*G3+H3) -> 0 | K3: =I3+J3 -> 699.2734 | L3: =MAX(0,K3*(1+_xlfn.NORM.INV(RAND(),LookupTables!$I$6,0.08))) -> 733.7466 | M3: =MIN(K3,L3) -> 699.2734 | N3: =MAX(0,K3-L3) -> 0 | O3: =MAX(0,L3-K3) -> 34.473201
A4: 45306 | B4: UK | C4: 39.4 | D4: =MONTH(A4) -> 1 | E4: =YEAR(A4) -> 2024 | F4: =VLOOKUP(B4,LookupTables!$A$2:$B$8,2,FALSE) -> 0.9 | G4: =INDEX(LookupTables!$F$2:$F$13,MATCH(D4,LookupTables!$D$2:$D$13,0)) -> 1.3 | H4: =_xlfn.NORM.INV(RAND(),LookupTables!$I$2,LookupTables!$I$3) -> 42.525526 | I4: =MAX(0,(100-C4)*LookupTables!$I$4*F4*G4+H4) -> 397.03553 | J4: =MAX(0,(C4-50)*LookupTables!$I$5*F4*G4+H4) -> 0 | K4: =I4+J4 -> 397.03553 | L4: =MAX(0,K4*(1+_xlfn.NORM.INV(RAND(),LookupTables!$I$6,0.08))) -> 433.71879 | M4: =MIN(K4,L4) -> 397.03553 | N4: =MAX(0,K4-L4) -> 0 | O4: =MAX(0,L4-K4) -> 36.683266
A5: 45313 | B5: Germany | C5: 36.5 | D5: =MONTH(A5) -> 1 | E5: =YEAR(A5) -> 2024 | F5: =VLOOKUP(B5,LookupTables!$A$2:$B$8,2,FALSE) -> 1.1 | G5: =INDEX(LookupTables!$F$2:$F$13,MATCH(D5,LookupTables!$D$2:$D$13,0)) -> 1.3 | H5: =_xlfn.NORM.INV(RAND(),LookupTables!$I$2,LookupTables!$I$3) -> -83.984031 | I5: =MAX(0,(100-C5)*LookupTables!$I$4*F5*G5+H5) -> 370.04097 | J5: =MAX(0,(C5-50)*LookupTables!$I$5*F5*G5+H5) -> 0 | K5: =I5+J5 -> 370.04097 | L5: =MAX(0,K5*(1+_xlfn.NORM.INV(RAND(),LookupTables!$I$6,0.08))) -> 407.447 | M5: =MIN(K5,L5) -> 370.04097 | N5: =MAX(0,K5-L5) -> 0 | O5: =MAX(0,L5-K5) -> 37.40603
A6: 45320 | B6: Australia | C6: 78.4 | D6: =MONTH(A6) -> 1 | E6: =YEAR(A6) -> 2024 | F6: =VLOOKUP(B6,LookupTables!$A$2:$B$8,2,FALSE) -> 0.85 | G6: =INDEX(LookupTables!$F$2:$F$13,MATCH(D6,LookupTables!$D$2:$D$13,0)) -> 1.3 | H6: =_xlfn.NORM.INV(RAND(),LookupTables!$I$2,LookupTables!$I$3) -> -31.482934 | I6: =MAX(0,(100-C6)*LookupTables!$I$4*F6*G6+H6) -> 87.857066 | J6: =MAX(0,(C6-50)*LookupTables!$I$5*F6*G6+H6) -> 125.42707 | K6: =I6+J6 -> 213.28413 | L6: =MAX(0,K6*(1+_xlfn.NORM.INV(RAND(),LookupTables!$I$6,0.08))) -> 251.58181 | M6: =MIN(K6,L6) -> 213.28413 | N6: =MAX(0,K6-L6) -> 0 | O6: =MAX(0,L6-K6) -> 38.297681
A7: 45327 | B7: Japan | C7: 36.5 | D7: =MONTH(A7) -> 2 | E7: =YEAR(A7) -> 2024 | F7: =VLOOKUP(B7,LookupTables!$A$2:$B$8,2,FALSE) -> 1.05 | G7: =INDEX(LookupTables!$F$2:$F$13,MATCH(D7,LookupTables!$D$2:$D$13,0)) -> 1.25 | H7: =_xlfn.NORM.INV(RAND(),LookupTables!$I$2,LookupTables!$I$3) -> 53.415857 | I7: =MAX(0,(100-C7)*LookupTables!$I$4*F7*G7+H7) -> 470.13461 | J7: =MAX(0,(C7-50)*LookupTables!$I$5*F7*G7+H7) -> 0 | K7: =I7+J7 -> 470.13461 | L7: =MAX(0,K7*(1+_xlfn.NORM.INV(RAND(),LookupTables!$I$6,0.08))) -> 575.07361 | M7: =MIN(K7,L7) -> 470.13461 | N7: =MAX(0,K7-L7) -> 0 | O7: =MAX(0,L7-K7) -> 104.939
A8: 45334 | B8: Brazil | C8: 82.7 | D8: =MONTH(A8) -> 2 | E8: =YEAR(A8) -> 2024 | F8: =VLOOKUP(B8,LookupTables!$A$2:$B$8,2,FALSE) -> 0.7 | G8: =INDEX(LookupTables!$F$2:$F$13,MATCH(D8,LookupTables!$D$2:$D$13,0)) -> 1.25 | H8: =_xlfn.NORM.INV(RAND(),LookupTables!$I$2,LookupTables!$I$3) -> -17.204465 | I8: =MAX(0,(100-C8)*LookupTables!$I$4*F8*G8+H8) -> 58.483035 | J8: =MAX(0,(C8-50)*LookupTables!$I$5*F8*G8+H8) -> 125.85804 | K8: =I8+J8 -> 184.34107 | L8: =MAX(0,K8*(1+_xlfn.NORM.INV(RAND(),LookupTables!$I$6,0.08))) -> 192.45906 | M8: =MIN(K8,L8) -> 184.34107 | N8: =MAX(0,K8-L8) -> 0 | O8: =MAX(0,L8-K8) -> 8.1179875
A9: 45341 | B9: USA | C9: 33.7 | D9: =MONTH(A9) -> 2 | E9: =YEAR(A9) -> 2024 | F9: =VLOOKUP(B9,LookupTables!$A$2:$B$8,2,FALSE) -> 1 | G9: =INDEX(LookupTables!$F$2:$F$13,MATCH(D9,LookupTables!$D$2:$D$13,0)) -> 1.25 | H9: =_xlfn.NORM.INV(RAND(),LookupTables!$I$2,LookupTables!$I$3) -> 78.745298 | I9: =MAX(0,(100-C9)*LookupTables!$I$4*F9*G9+H9) -> 493.1203 | J9: =MAX(0,(C9-50)*LookupTables!$I$5*F9*G9+H9) -> 0 | K9: =I9+J9 -> 493.1203 | L9: =MAX(0,K9*(1+_xlfn.NORM.INV(RAND(),LookupTables!$I$6,0.08))) -> 502.10694 | M9: =MIN(K9,L9) -> 493.1203 | N9: =MAX(0,K9-L9) -> 0 | O9: =MAX(0,L9-K9) -> 8.9866442
A10: 45348 | B10: Canada | C10: 16.9 | D10: =MONTH(A10) -> 2 | E10: =YEAR(A10) -> 2024 | F10: =VLOOKUP(B10,LookupTables!$A$2:$B$8,2,FALSE) -> 1.2 | G10: =INDEX(LookupTables!$F$2:$F$13,MATCH(D10,LookupTables!$D$2:$D$13,0)) -> 1.25 | H10: =_xlfn.NORM.INV(RAND(),LookupTables!$I$2,LookupTables!$I$3) -> 34.800461 | I10: =MAX(0,(100-C10)*LookupTables!$I$4*F10*G10+H10) -> 658.05046 | J10: =MAX(0,(C10-50)*LookupTables!$I$5*F10*G10+H10) -> 0 | K10: =I10+J10 -> 658.05046 | L10: =MAX(0,K10*(1+_xlfn.NORM.INV(RAND(),LookupTables!$I$6,0.08))) -> 751.96768 | M10: =MIN(K10,L10) -> 658.05046 | N10: =MAX(0,K10-L10) -> 0 | O10: =MAX(0,L10-K10) -> 93.917218
A11: 45355 | B11: UK | C11: 45.6 | D11: =MONTH(A11) -> 3 | E11: =YEAR(A11) -> 2024 | F11: =VLOOKUP(B11,LookupTables!$A$2:$B$8,2,FALSE) -> 0.9 | G11: =INDEX(LookupTables!$F$2:$F$13,MATCH(D11,LookupTables!$D$2:$D$13,0)) -> 0.8 | H11: =_xlfn.NORM.INV(RAND(),LookupTables!$I$2,LookupTables!$I$3) -> -18.344449 | I11: =MAX(0,(100-C11)*LookupTables!$I$4*F11*G11+H11) -> 177.49555 | J11: =MAX(0,(C11-50)*LookupTables!$I$5*F11*G11+H11) -> 0 | K11: =I11+J11 -> 177.49555 | L11: =MAX(0,K11*(1+_xlfn.NORM.INV(RAND(),LookupTables!$I$6,0.08))) -> 165.24883 | M11: =MIN(K11,L11) -> 165.24883 | N11: =MAX(0,K11-L11) -> 12.24672 | O11: =MAX(0,L11-K11) -> 0
A12: 45362 | B12: Germany | C12: 44.2 | D12: =MONTH(A12) -> 3 | E12: =YEAR(A12) -> 2024 | F12: =VLOOKUP(B12,LookupTables!$A$2:$B$8,2,FALSE) -> 1.1 | G12: =INDEX(LookupTables!$F$2:$F$13,MATCH(D12,LookupTables!$D$2:$D$13,0)) -> 0.8 | H12: =_xlfn.NORM.INV(RAND(),LookupTables!$I$2,LookupTables!$I$3) -> -33.882223 | I12: =MAX(0,(100-C12)*LookupTables!$I$4*F12*G12+H12) -> 211.63778 | J12: =MAX(0,(C12-50)*LookupTables!$I$5*F12*G12+H12) -> 0 | K12: =I12+J12 -> 211.63778 | L12: =MAX(0,K12*(1+_xlfn.NORM.INV(RAND(),LookupTables!$I$6,0.08))) -> 224.78362 | M12: =MIN(K12,L12) -> 211.63778 | N12: =MAX(0,K12-L12) -> 0 | O12: =MAX(0,L12-K12) -> 13.14584
A13: 45369 | B13: Australia | C13: 79.8 | D13: =MONTH(A13) -> 3 | E13: =YEAR(A13) -> 2024 | F13: =VLOOKUP(B13,LookupTables!$A$2:$B$8,2,FALSE) -> 0.85 | G13: =INDEX(LookupTables!$F$2:$F$13,MATCH(D13,LookupTables!$D$2:$D$13,0)) -> 0.8 | H13: =_xlfn.NORM.INV(RAND(),LookupTables!$I$2,LookupTables!$I$3) -> 16.50767 | I13: =MAX(0,(100-C13)*LookupTables!$I$4*F13*G13+H13) -> 85.18767 | J13: =MAX(0,(C13-50)*LookupTables!$I$5*F13*G13+H13) -> 117.82767 | K13: =I13+J13 -> 203.01534 | L13: =MAX(0,K13*(1+_xlfn.NORM.INV(RAND(),LookupTables!$I$6,0.08))) -> 238.94744 | M13: =MIN(K13,L13) -> 203.01534 | N13: =MAX(0,K13-L13) -> 0 | O13: =MAX(0,L13-K13) -> 35.932104
... A105: 46013 | B105: Japan | C105: 39.4 | D105: =MONTH(A105) -> 12 | E105: =YEAR(A105) -> 2025 | F105: =VLOOKUP(B105,LookupTables!$A$2:$B$8,2,FALSE) -> 1.05 | G105: =INDEX(LookupTables!$F$2:$F$13,MATCH(D105,LookupTables!$D$2:$D$13,0)) -> 1.4 | H105: =_xlfn.NORM.INV(RAND(),LookupTables!$I$2,LookupTables!$I$3) -> 29.124696 | I105: =MAX(0,(100-C105)*LookupTables!$I$4*F105*G105+H105) -> 474.5347 | J105: =MAX(0,(C105-50)*LookupTables!$I$5*F105*G105+H105) -> 0 | K105: =I105+J105 -> 474.5347 | L105: =MAX(0,K105*(1+_xlfn.NORM.INV(RAND(),LookupTables!$I$6,0.08))) -> 502.18535 | M105: =MIN(K105,L105) -> 474.5347 | N105: =MAX(0,K105-L105) -> 0 | O105: =MAX(0,L105-K105) -> 27.65065
A107: TOTALS | J107: Column Sums: | K107: =SUM(K2:K105) -> 29957.621 | L107: =SUM(L2:L105) -> 33077.865 | M107: =SUM(M2:M105) -> 29855.714 | N107: =SUM(N2:N105) -> 101.90746 | O107: =SUM(O2:O105) -> 3222.1508
A108: AVERAGES | C108: =AVERAGE(C2:C105) -> 58.149038 | J108: Column Averages: | K108: =AVERAGE(K2:K105) -> 288.05405 | L108: =AVERAGE(L2:L105) -> 318.05639 | M108: =AVERAGE(M2:M105) -> 287.07417 | N108: =AVERAGE(N2:N105) -> 0.97987946 | O108: =AVERAGE(O2:O105) -> 30.982219

Sheet Sheet1
A1: Year | B1: Month | C1: Country | D1: AvgTemp
A2: 2000 | B2: 2 | C2: Denmark | D2: 3.6475
A3: 2000 | B3: 3 | C3: Denmark | D3: 4.0005
A4: 2000 | B4: 4 | C4: Denmark | D4: 8.4615
A5: 2000 | B5: 5 | C5: Denmark | D5: 13.6475
A6: 2000 | B6: 6 | C6: Denmark | D6: 15.002
A7: 2000 | B7: 7 | C7: Denmark | D7: 16.2495
A8: 2000 | B8: 8 | C8: Denmark | D8: 16.25
A9: 2000 | B9: 9 | C9: Denmark | D9: 13.504
A10: 2000 | B10: 10 | C10: Denmark | D10: 11.091
A11: 2000 | B11: 11 | C11: Denmark | D11: 6.9995
A12: 2000 | B12: 12 | C12: Denmark | D12: 3.5975
A13: 2001 | B13: 1 | C13: Denmark | D13: 1.7405
... A25933: 2013 | B25933: 8 | C25933: Namibia | D25933: 17.06

Sheet Global Land Temperatures (CA)
A1: Date | B1: Year | C1: Month | D1: Country | E1: AvgTemp (C) | F1: AvgTemp (F) | G1: CountryFactor | H1: SeasonFactor | I1: Noise | J1: Winter_Demand | K1: Summer_Demand | L1: Total_Demand | M1: Inventory | N1: Sales | O1: Lost_Sales | P1: Excess_Inventory | R1: Date | S1: Forecast temperature | T1: Forecast winter demand | U1: Forecast summer demand | V1: Forecast Inventory | W1: Sales | X1: Lost_Sales | Y1: Excess Inventory
B2: 2000 | C2: 2 | D2: Denmark | E2: 3.6475 | F2: =(E2 * 1.8) + 32 -> 38.5655 | H2: =VLOOKUP(D2,LookupTables!$A$2:$B$8,2,FALSE) -> #N/A | I2: =INDEX(LookupTables!$F$2:$F$13,MATCH(F2,LookupTables!$D$2:$D$13,0)) -> #N/A | J2: =_xlfn.NORM.INV(RAND(),LookupTables!$I$2,LookupTables!$I$3) -> -7.2232537 | K2: =MAX(0,(100-E2)*LookupTables!$I$4*H2*I2+J2) -> #N/A | L2: =MAX(0,(E2-50)*LookupTables!$I$5*H2*I2+J2) -> #N/A | M2: =K2+L2 -> #N/A | N2: =MAX(0,M2*(1+_xlfn.NORM.INV(RAND(),LookupTables!$I$6,0.08))) -> #N/A | O2: =MIN(M2,N2) -> #N/A | P2: =MAX(0,M2-N2) -> #N/A | Q2: =MAX(0,N2-M2) -> #N/A | R2: 41275 | S2: -6.319 | T2: 624 | U2: 0 | V2: 707 | W2: 624 | X2: 0 | Y2: 83
B3: 2000 | C3: 3 | D3: Denmark | E3: 4.0005 | F3: =(E3 * 1.8) + 32 -> 39.2009 | H3: =VLOOKUP(D3,LookupTables!$A$2:$B$8,2,FALSE) -> #N/A | I3: =INDEX(LookupTables!$F$2:$F$13,MATCH(F3,LookupTables!$D$2:$D$13,0)) -> #N/A | J3: =_xlfn.NORM.INV(RAND(),LookupTables!$I$2,LookupTables!$I$3) -> -67.583391 | K3: =MAX(0,(100-E3)*LookupTables!$I$4*H3*I3+J3) -> #N/A | L3: =MAX(0,(E3-50)*LookupTables!$I$5*H3*I3+J3) -> #N/A | M3: =K3+L3 -> #N/A | N3: =MAX(0,M3*(1+_xlfn.NORM.INV(RAND(),LookupTables!$I$6,0.08))) -> #N/A | O3: =MIN(M3,N3) -> #N/A | P3: =MAX(0,M3-N3) -> #N/A | Q3: =MAX(0,N3-M3) -> #N/A | R3: 41306 | S3: -6.501 | T3: 560 | U3: 0 | V3: 600 | W3: 560 | X3: 0 | Y3: 40
B4: 2000 | C4: 4 | D4: Denmark | E4: 8.4615 | F4: =(E4 * 1.8) + 32 -> 47.2307 | H4: =VLOOKUP(D4,LookupTables!$A$2:$B$8,2,FALSE) -> #N/A | I4: =INDEX(LookupTables!$F$2:$F$13,MATCH(F4,LookupTables!$D$2:$D$13,0)) -> #N/A | J4: =_xlfn.NORM.INV(RAND(),LookupTables!$I$2,LookupTables!$I$3) -> 101.43098 | K4: =MAX(0,(100-E4)*LookupTables!$I$4*H4*I4+J4) -> #N/A | L4: =MAX(0,(E4-50)*LookupTables!$I$5*H4*I4+J4) -> #N/A | M4: =K4+L4 -> #N/A | N4: =MAX(0,M4*(1+_xlfn.NORM.INV(RAND(),LookupTables!$I$6,0.08))) -> #N/A | O4: =MIN(M4,N4) -> #N/A | P4: =MAX(0,M4-N4) -> #N/A | Q4: =MAX(0,N4-M4) -> #N/A | R4: 41334 | S4: -2.334 | T4: 0 | U4: 0 | V4: 0 | W4: 0 | X4: 0 | Y4: 0
B5: 2000 | C5: 5 | D5: Denmark | E5: 13.6475 | F5: =(E5 * 1.8) + 32 -> 56.5655 | H5: =VLOOKUP(D5,LookupTables!$A$2:$B$8,2,FALSE) -> #N/A | I5: =INDEX(LookupTables!$F$2:$F$13,MATCH(F5,LookupTables!$D$2:$D$13,0)) -> #N/A | J5: =_xlfn.NORM.INV(RAND(),LookupTables!$I$2,LookupTables!$I$3) -> 32.802752 | K5: =MAX(0,(100-E5)*LookupTables!$I$4*H5*I5+J5) -> #N/A | L5: =MAX(0,(E5-50)*LookupTables!$I$5*H5*I5+J5) -> #N/A | M5: =K5+L5 -> #N/A | N5: =MAX(0,M5*(1+_xlfn.NORM.INV(RAND(),LookupTables!$I$6,0.08))) -> #N/A | O5: =MIN(M5,N5) -> #N/A | P5: =MAX(0,M5-N5) -> #N/A | Q5: =MAX(0,N5-M5) -> #N/A | R5: 41365 | S5: 5.087 | T5: 0 | U5: 0 | V5: 0 | W5: 0 | X5: 0 | Y5: 0
B6: 2000 | C6: 6 | D6: Denmark | E6: 15.002 | F6: =(E6 * 1.8) + 32 -> 59.0036 | H6: =VLOOKUP(D6,LookupTables!$A$2:$B$8,2,FALSE) -> #N/A | I6: =INDEX(LookupTables!$F$2:$F$13,MATCH(F6,LookupTables!$D$2:$D$13,0)) -> #N/A | J6: =_xlfn.NORM.INV(RAND(),LookupTables!$I$2,LookupTables!$I$3) -> 26.85189 | K6: =MAX(0,(100-E6)*LookupTables!$I$4*H6*I6+J6) -> #N/A | L6: =MAX(0,(E6-50)*LookupTables!$I$5*H6*I6+J6) -> #N/A | M6: =K6+L6 -> #N/A | N6: =MAX(0,M6*(1+_xlfn.NORM.INV(RAND(),LookupTables!$I$6,0.08))) -> #N/A | O6: =MIN(M6,N6) -> #N/A | P6: =MAX(0,M6-N6) -> #N/A | Q6: =MAX(0,N6-M6) -> #N/A | R6: 41395 | S6: 11.448 | T6: 0 | U6: 33 | V6: 43 | W6: 33 | X6: 0 | Y6: 10
B7: 2000 | C7: 7 | D7: Denmark | E7: 16.2495 | F7: =(E7 * 1.8) + 32 -> 61.2491 | H7: =VLOOKUP(D7,LookupTables!$A$2:$B$8,2,FALSE) -> #N/A | I7: =INDEX(LookupTables!$F$2:$F$13,MATCH(F7,LookupTables!$D$2:$D$13,0)) -> #N/A | J7: =_xlfn.NORM.INV(RAND(),LookupTables!$I$2,LookupTables!$I$3) -> 79.843532 | K7: =MAX(0,(100-E7)*LookupTables!$I$4*H7*I7+J7) -> #N/A | L7: =MAX(0,(E7-50)*LookupTables!$I$5*H7*I7+J7) -> #N/A | M7: =K7+L7 -> #N/A | N7: =MAX(0,M7*(1+_xlfn.NORM.INV(RAND(),LookupTables!$I$6,0.08))) -> #N/A | O7: =MIN(M7,N7) -> #N/A | P7: =MAX(0,M7-N7) -> #N/A | Q7: =MAX(0,N7-M7) -> #N/A | R7: 41426 | S7: 16.632 | T7: 0 | U7: 47 | V7: 56 | W7: 47 | X7: 0 | Y7: 9
B8: 2000 | C8: 8 | D8: Denmark | E8: 16.25 | F8: =(E8 * 1.8) + 32 -> 61.25 | H8: =VLOOKUP(D8,LookupTables!$A$2:$B$8,2,FALSE) -> #N/A | I8: =INDEX(LookupTables!$F$2:$F$13,MATCH(F8,LookupTables!$D$2:$D$13,0)) -> #N/A | J8: =_xlfn.NORM.INV(RAND(),LookupTables!$I$2,LookupTables!$I$3) -> -49.305276 | K8: =MAX(0,(100-E8)*LookupTables!$I$4*H8*I8+J8) -> #N/A | L8: =MAX(0,(E8-50)*LookupTables!$I$5*H8*I8+J8) -> #N/A | M8: =K8+L8 -> #N/A | N8: =MAX(0,M8*(1+_xlfn.NORM.INV(RAND(),LookupTables!$I$6,0.08))) -> #N/A | O8: =MIN(M8,N8) -> #N/A | P8: =MAX(0,M8-N8) -> #N/A | Q8: =MAX(0,N8-M8) -> #N/A | R8: 41456 | S8: 18.942 | T8: 0 | U8: 129 | V8: 127 | W8: 127 | X8: 0 | Y8: 0
B9: 2000 | C9: 9 | D9: Denmark | E9: 13.504 | F9: =(E9 * 1.8) + 32 -> 56.3072 | H9: =VLOOKUP(D9,LookupTables!$A$2:$B$8,2,FALSE) -> #N/A | I9: =INDEX(LookupTables!$F$2:$F$13,MATCH(F9,LookupTables!$D$2:$D$13,0)) -> #N/A | J9: =_xlfn.NORM.INV(RAND(),LookupTables!$I$2,LookupTables!$I$3) -> -7.3361901 | K9: =MAX(0,(100-E9)*LookupTables!$I$4*H9*I9+J9) -> #N/A | L9: =MAX(0,(E9-50)*LookupTables!$I$5*H9*I9+J9) -> #N/A | M9: =K9+L9 -> #N/A | N9: =MAX(0,M9*(1+_xlfn.NORM.INV(RAND(),LookupTables!$I$6,0.08))) -> #N/A | O9: =MIN(M9,N9) -> #N/A | P9: =MAX(0,M9-N9) -> #N/A | Q9: =MAX(0,N9-M9) -> #N/A | R9: 41487 | S9: 18.964 | T9: 0 | U9: 52 | V9: 56 | W9: 52 | X9: 0 | Y9: 4
B10: 2000 | C10: 10 | D10: Denmark | E10: 11.091 | F10: =(E10 * 1.8) + 32 -> 51.9638 | H10: =VLOOKUP(D10,LookupTables!$A$2:$B$8,2,FALSE) -> #N/A | I10: =INDEX(LookupTables!$F$2:$F$13,MATCH(F10,LookupTables!$D$2:$D$13,0)) -> #N/A | J10: =_xlfn.NORM.INV(RAND(),LookupTables!$I$2,LookupTables!$I$3) -> -2.9825692 | K10: =MAX(0,(100-E10)*LookupTables!$I$4*H10*I10+J10) -> #N/A | L10: =MAX(0,(E10-50)*LookupTables!$I$5*H10*I10+J10) -> #N/A | M10: =K10+L10 -> #N/A | N10: =MAX(0,M10*(1+_xlfn.NORM.INV(RAND(),LookupTables!$I$6,0.08))) -> #N/A | O10: =MIN(M10,N10) -> #N/A | P10: =MAX(0,M10-N10) -> #N/A | Q10: =MAX(0,N10-M10) -> #N/A | R10: 41518 | S10: 14.713 | T10: 191 | U10: 9 | V10: 230 | W10: 200 | X10: 0 | Y10: 30
B11: 2000 | C11: 11 | D11: Denmark | E11: 6.9995 | F11: =(E11 * 1.8) + 32 -> 44.5991 | H11: =VLOOKUP(D11,LookupTables!$A$2:$B$8,2,FALSE) -> #N/A | I11: =INDEX(LookupTables!$F$2:$F$13,MATCH(F11,LookupTables!$D$2:$D$13,0)) -> #N/A | J11: =_xlfn.NORM.INV(RAND(),LookupTables!$I$2,LookupTables!$I$3) -> -66.606298 | K11: =MAX(0,(100-E11)*LookupTables!$I$4*H11*I11+J11) -> #N/A | L11: =MAX(0,(E11-50)*LookupTables!$I$5*H11*I11+J11) -> #N/A | M11: =K11+L11 -> #N/A | N11: =MAX(0,M11*(1+_xlfn.NORM.INV(RAND(),LookupTables!$I$6,0.08))) -> #N/A | O11: =MIN(M11,N11) -> #N/A | P11: =MAX(0,M11-N11) -> #N/A | Q11: =MAX(0,N11-M11) -> #N/A | R11: 41548 | S11: 7.487 | T11: 228 | U11: 5 | V11: 259 | W11: 233 | X11: 0 | Y11: 26
B12: 2000 | C12: 12 | D12: Denmark | E12: 3.5975 | F12: =(E12 * 1.8) + 32 -> 38.4755 | H12: =VLOOKUP(D12,LookupTables!$A$2:$B$8,2,FALSE) -> #N/A | I12: =INDEX(LookupTables!$F$2:$F$13,MATCH(F12,LookupTables!$D$2:$D$13,0)) -> #N/A | J12: =_xlfn.NORM.INV(RAND(),LookupTables!$I$2,LookupTables!$I$3) -> 70.704133 | K12: =MAX(0,(100-E12)*LookupTables!$I$4*H12*I12+J12) -> #N/A | L12: =MAX(0,(E12-50)*LookupTables!$I$5*H12*I12+J12) -> #N/A | M12: =K12+L12 -> #N/A | N12: =MAX(0,M12*(1+_xlfn.NORM.INV(RAND(),LookupTables!$I$6,0.08))) -> #N/A | O12: =MIN(M12,N12) -> #N/A | P12: =MAX(0,M12-N12) -> #N/A | Q12: =MAX(0,N12-M12) -> #N/A | R12: 41579 | S12: 2.25 | T12: 340 | U12: 0 | V12: 362 | W12: 340 | X12: 0 | Y12: 23
B13: 2001 | C13: 1 | D13: Denmark | E13: 1.7405 | F13: =(E13 * 1.8) + 32 -> 35.1329 | H13: =VLOOKUP(D13,LookupTables!$A$2:$B$8,2,FALSE) -> #N/A | I13: =INDEX(LookupTables!$F$2:$F$13,MATCH(F13,LookupTables!$D$2:$D$13,0)) -> #N/A | J13: =_xlfn.NORM.INV(RAND(),LookupTables!$I$2,LookupTables!$I$3) -> -33.520026 | K13: =MAX(0,(100-E13)*LookupTables!$I$4*H13*I13+J13) -> #N/A | L13: =MAX(0,(E13-50)*LookupTables!$I$5*H13*I13+J13) -> #N/A | M13: =K13+L13 -> #N/A | N13: =MAX(0,M13*(1+_xlfn.NORM.INV(RAND(),LookupTables!$I$6,0.08))) -> #N/A | O13: =MIN(M13,N13) -> #N/A | P13: =MAX(0,M13-N13) -> #N/A | Q13: =MAX(0,N13-M13) -> #N/A | R13: 41609 | S13: -4.723 | T13: 616 | U13: 0 | V13: 708 | W13: 616 | X13: 0 | Y13: 92
... B105: 2008 | C105: 9 | D105: Denmark | E105: 13.568 | F105: =(E105 * 1.8) + 32 -> 56.4224 | H105: =VLOOKUP(D105,LookupTables!$A$2:$B$8,2,FALSE) -> #N/A | I105: =INDEX(LookupTables!$F$2:$F$13,MATCH(F105,LookupTables!$D$2:$D$13,0)) -> #N/A | J105: =_xlfn.NORM.INV(RAND(),LookupTables!$I$2,LookupTables!$I$3) -> -69.393384 | K105: =MAX(0,(100-E105)*LookupTables!$I$4*H105*I105+J105) -> #N/A | L105: =MAX(0,(E105-50)*LookupTables!$I$5*H105*I105+J105) -> #N/A | M105: =K105+L105 -> #N/A | N105: =MAX(0,M105*(1+_xlfn.NORM.INV(RAND(),LookupTables!$I$6,0.08))) -> #N/A | O105: =MIN(M105,N105) -> #N/A | P105: =MAX(0,M105-N105) -> #N/A | Q105: =MAX(0,N105-M105) -> #N/A | R105: 44409 | S105: 19.249 | T105: 0 | U105: 36 | V105: 42 | W105: 36 | X105: 0 | Y105: 6
B106: 2008 | C106: 10 | D106: Denmark | E106: 9.7065 | F106: =(E106 * 1.8) + 32 -> 49.4717 | M106: Canada | N106: 35.06965 | O106: 11 | R106: 44440 | S106: 14.999 | T106: 166 | U106: 0 | V106: 204 | W106: 166 | X106: 0 | Y106: 38
B107: 2008 | C107: 11 | D107: Denmark | E107: 5.6575 | F107: =(E107 * 1.8) + 32 -> 42.1835 | M107: Canada | N107: 18.39913 | O107: 12 | R107: 44470 | S107: 7.772 | T107: 203 | U107: 0 | V107: 259 | W107: 203 | X107: 0 | Y107: 56
B108: 2008 | C108: 12 | D108: Denmark | E108: 2.31 | F108: =(E108 * 1.8) + 32 -> 36.158 | M108: Canada | N108: 12.68168 | O108: 1 | R108: 44501 | S108: 2.535 | T108: 314 | U108: 0 | V108: 313 | W108: 313 | X108: 0 | Y108: 0
B109: 2009 | C109: 1 | D109: Denmark | E109: 0.8495 | F109: =(E109 * 1.8) + 32 -> 33.5291 | M109: Canada | N109: 20.15161 | O109: 2 | R109: 44531 | S109: -4.437 | T109: 591 | U109: 0 | V109: 775 | W109: 591 | X109: 0 | Y109: 185
B110: 2009 | C110: 2 | D110: Denmark | E110: 0.5275 | F110: =(E110 * 1.8) + 32 -> 32.9495 | M110: Canada | N110: 27.57747 | O110: 3 | R110: 44562 | S110: -5.997 | T110: 595 | U110: 0 | V110: 631 | W110: 595 | X110: 0 | Y110: 36
B111: 2009 | C111: 3 | D111: Denmark | E111: 3.949 | F111: =(E111 * 1.8) + 32 -> 39.1082 | M111: Canada | N111: 41.76824 | O111: 4 | R111: 44593 | S111: -6.179 | T111: 531 | U111: 0 | V111: 544 | W111: 531 | X111: 0 | Y111: 13
B112: 2009 | C112: 4 | D112: Denmark | E112: 9.5085 | F112: =(E112 * 1.8) + 32 -> 49.1153 | M112: Canada | N112: 51.28369 | O112: 5 | R112: 44621 | S112: -2.012 | T112: 0 | U112: 0 | V112: 0 | W112: 0 | X112: 0 | Y112: 0
B113: 2009 | C113: 5 | D113: Denmark | E113: 12.4455 | F113: =(E113 * 1.8) + 32 -> 54.4019 | M113: Canada | N113: 59.81216 | O113: 6 | R113: 44652 | S113: 5.409 | T113: 0 | U113: 0 | V113: 0 | W113: 0 | X113: 0 | Y113: 0
B114: 2009 | C114: 6 | D114: Denmark | E114: 15.158 | F114: =(E114 * 1.8) + 32 -> 59.2844 | M114: Canada | N114: 63.46105 | O114: 7 | R114: 44682 | S114: 11.769 | T114: 0 | U114: 14 | V114: 17 | W114: 14 | X114: 0 | Y114: 3
B115: 2009 | C115: 7 | D115: Denmark | E115: 18.4115 | F115: =(E115 * 1.8) + 32 -> 65.1407 | M115: Canada | N115: 64.57251 | O115: 8 | R115: 44713 | S115: 16.954 | T115: 0 | U115: 28 | V115: 33 | W115: 28 | X115: 0 | Y115: 4
B116: 2009 | C116: 8 | D116: Denmark | E116: 18.0555 | F116: =(E116 * 1.8) + 32 -> 64.4999 | M116: Canada | N116: 58.62344 | O116: 9 | R116: 44743 | S116: 19.264 | T116: 0 | U116: 111 | V116: 107 | W116: 107 | X116: 0 | Y116: 0
B117: 2009 | C117: 9 | D117: Denmark | E117: 14.7685 | F117: =(E117 * 1.8) + 32 -> 58.5833 | M117: Canada | N117: 42.39385 | O117: 10 | R117: 44774 | S117: 19.285 | T117: 0 | U117: 34 | V117: 39 | W117: 34 | X117: 0 | Y117: 6
... B164: 2013 | C164: 8 | D164: Denmark | E164: 17.745 | F164: =(E164 * 1.8) + 32 -> 63.941 | M164: Canada | N164: 58.48383 | O164: 9 | R164: 46204 | S164: 19.407 | T164: 0 | U164: 102 | V164: 106 | W164: 102 | X164: 0 | Y164: 4
B165: 2000 | C165: 2 | D165: Turkey | E165: 2.9882353 | F165: =(E165 * 1.8) + 32 -> 37.378824 | R165: 46235 | S165: 19.428 | T165: 0 | U165: 25 | V165: 29 | W165: 25 | X165: 0 | Y165: 4
B166: 2000 | C166: 3 | D166: Turkey | E166: 6.0615098 | F166: =(E166 * 1.8) + 32 -> 42.910718
B167: 2000 | C167: 4 | D167: Turkey | E167: 13.528667 | F167: =(E167 * 1.8) + 32 -> 56.3516
B168: 2000 | C168: 5 | D168: Turkey | E168: 16.585451 | F168: =(E168 * 1.8) + 32 -> 61.853812
B169: 2000 | C169: 6 | D169: Turkey | E169: 21.348471 | F169: =(E169 * 1.8) + 32 -> 70.427247
B170: 2000 | C170: 7 | D170: Turkey | E170: 26.047745 | F170: =(E170 * 1.8) + 32 -> 78.885941
B171: 2000 | C171: 8 | D171: Turkey | E171: 24.407373 | F171: =(E171 * 1.8) + 32 -> 75.933271
B172: 2000 | C172: 9 | D172: Turkey | E172: 20.620627 | F172: =(E172 * 1.8) + 32 -> 69.117129
B173: 2000 | C173: 10 | D173: Turkey | E173: 14.320804 | F173: =(E173 * 1.8) + 32 -> 57.777447
B174: 2000 | C174: 11 | D174: Turkey | E174: 10.619882 | F174: =(E174 * 1.8) + 32 -> 51.115788
B175: 2000 | C175: 12 | D175: Turkey | E175: 5.4920196 | F175: =(E175 * 1.8) + 32 -> 41.885635
B176: 2001 | C176: 1 | D176: Turkey | E176: 5.0632353 | F176: =(E176 * 1.8) + 32 -> 41.113824
B177: 2001 | C177: 2 | D177: Turkey | E177: 5.6956863 | F177: =(E177 * 1.8) + 32 -> 42.252235
...

Sheet Global Land Temperatures (US)
A1: Date | B1: Year | C1: Month | D1: Country | E1: AvgTemp (C) | F1: AvgTemp (F) | G1: CountryFactor | H1: SeasonFactor | I1: Noise | J1: Winter_Demand | K1: Summer_Demand | L1: Total_Demand | M1: Inventory | N1: Sales | O1: Lost_Sales | P1: Excess_Inventory | R1: Forecasted Date | S1: Forecast temperature | T1: Forecast winter demand | U1: Forecast summer demand | V1: Forecast Inventory | W1: Sales | X1: Lost_Sales | Y1: Excess Inventory
A2: =DATE(B2,C2,1) -> 36557 | B2: 2000 | C2: 2 | D2: United States | E2: 8.1159027 | F2: =(E2*1.8) +32 -> 46.608625 | G2: 1 | H2: 1.25 | I2: =_xlfn.NORM.INV(RAND(),LookupTables!$I$2,LookupTables!$I$3) -> 67.240836 | J2: =IF(AND(C2>=3,C2<=8),0,MAX(0,(100-F2)*LookupTables!$I$4*G2*H2+I2)) | K2: =ROUND(MAX(0,(F2-50)*LookupTables!$I$5*G2*H2+I2),0) | L2: =J2+K2 -> 641.51644 | M2: =MAX(0,L2*(1+_xlfn.NORM.INV(RAND(),LookupTables!$I$6,0.08))) -> 719.87666 | N2: =MIN(L2,M2) -> 641.51644 | O2: =MAX(L2-M2,0) | P2: =MAX(M2-L2,0) | R2: =DATE(2013,10,1) -> 41548 | S2: =MAX(0,_xlfn.FORECAST.ETS(R2,$E$2:$E$165,$A$2:$A$165,12)) -> 15.852996 | T2: =IF(AND(MONTH(R2)>=3,MONTH(R2)<=8),0,MAX(0,(100-(S2*1.8+32))*LookupTables!$I$4*$G$2*INDEX(LookupTables!$F$2:$F$13,MATCH(MONTH(R2),LookupTables!$D$2:$D$13,0))+_xlfn.NORM.INV(RAND(),LookupTables!$I$2,LookupTables!$I$3))) | U2: =ROUND(MAX(0,((S2*1.8+32)-50)*LookupTables!$I$5*$G$2*INDEX(LookupTables!$F$2:$F$13,MATCH(MONTH(R2),LookupTables!$D$2:$D$13,0))+_xlfn.NORM.INV(RAND(),LookupTables!$I$2,LookupTables!$I$3)),0) | V2: =MAX(0,(T2+U2)*(1+_xlfn.NORM.INV(RAND(),LookupTables!$I$6,0.08))) -> #N/A | W2: =MIN(T2+U2,V2) -> #N/A | X2: =MAX((T2+U2)-V2,0) | Y2: =MAX(V2-(T2+U2),0)
A3: =DATE(B3,C3,1) -> 36586 | B3: 2000 | C3: 3 | D3: United States | E3: 11.347584 | F3: =(E3*1.8) +32 -> 52.425651 | G3: 1 | H3: 0.8 | I3: =_xlfn.NORM.INV(RAND(),LookupTables!$I$2,LookupTables!$I$3) -> 37.098715 | J3: =IF(AND(C3>=3,C3<=8),0,MAX(0,(100-F3)*LookupTables!$I$4*G3*H3+I3)) | K3: =ROUND(MAX(0,(F3-50)*LookupTables!$I$5*G3*H3+I3),0) | L3: =J3+K3 -> 0 | M3: =MAX(0,L3*(1+_xlfn.NORM.INV(RAND(),LookupTables!$I$6,0.08))) -> 0 | N3: =MIN(L3,M3) -> 0 | O3: =MAX(L3-M3,0) | P3: =MAX(M3-L3,0) | R3: =EDATE(R2,1) -> 41579 | S3: =MAX(0,_xlfn.FORECAST.ETS(R3,$E$2:$E$165,$A$2:$A$165,12)) -> #N/A | T3: =IF(AND(MONTH(R3)>=3,MONTH(R3)<=8),0,MAX(0,(100-(S3*1.8+32))*LookupTables!$I$4*$G$2*INDEX(LookupTables!$F$2:$F$13,MATCH(MONTH(R3),LookupTables!$D$2:$D$13,0))+_xlfn.NORM.INV(RAND(),LookupTables!$I$2,LookupTables!$I$3))) | U3: =ROUND(MAX(0,((S3*1.8+32)-50)*LookupTables!$I$5*$G$2*INDEX(LookupTables!$F$2:$F$13,MATCH(MONTH(R3),LookupTables!$D$2:$D$13,0))+_xlfn.NORM.INV(RAND(),LookupTables!$I$2,LookupTables!$I$3)),0) | V3: =MAX(0,(T3+U3)*(1+_xlfn.NORM.INV(RAND(),LookupTables!$I$6,0.08))) -> #N/A | W3: =MIN(T3+U3,V3) -> #N/A | X3: =MAX((T3+U3)-V3,0) | Y3: =MAX(V3-(T3+U3),0)
A4: =DATE(B4,C4,1) -> 36617 | B4: 2000 | C4: 4 | D4: United States | E4: 14.126549 | F4: =(E4*1.8) +32 -> 57.427788 | G4: 1 | H4: 0.7 | I4: =_xlfn.NORM.INV(RAND(),LookupTables!$I$2,LookupTables!$I$3) -> 6.6972072 | J4: =IF(AND(C4>=3,C4<=8),0,MAX(0,(100-F4)*LookupTables!$I$4*G4*H4+I4)) | K4: =ROUND(MAX(0,(F4-50)*LookupTables!$I$5*G4*H4+I4),0) | L4: =J4+K4 -> 0 | M4: =MAX(0,L4*(1+_xlfn.NORM.INV(RAND(),LookupTables!$I$6,0.08))) -> 0 | N4: =MIN(L4,M4) -> 0 | O4: =MAX(L4-M4,0) | P4: =MAX(M4-L4,0) | R4: =EDATE(R3,1) -> 41609 | S4: =MAX(0,_xlfn.FORECAST.ETS(R4,$E$2:$E$165,$A$2:$A$165,12)) -> 5.8342233 | T4: =IF(AND(MONTH(R4)>=3,MONTH(R4)<=8),0,MAX(0,(100-(S4*1.8+32))*LookupTables!$I$4*$G$2*INDEX(LookupTables!$F$2:$F$13,MATCH(MONTH(R4),LookupTables!$D$2:$D$13,0))+_xlfn.NORM.INV(RAND(),LookupTables!$I$2,LookupTables!$I$3))) | U4: =ROUND(MAX(0,((S4*1.8+32)-50)*LookupTables!$I$5*$G$2*INDEX(LookupTables!$F$2:$F$13,MATCH(MONTH(R4),LookupTables!$D$2:$D$13,0))+_xlfn.NORM.INV(RAND(),LookupTables!$I$2,LookupTables!$I$3)),0) | V4: =MAX(0,(T4+U4)*(1+_xlfn.NORM.INV(RAND(),LookupTables!$I$6,0.08))) -> #N/A | W4: =MIN(T4+U4,V4) -> #N/A | X4: =MAX((T4+U4)-V4,0) | Y4: =MAX(V4-(T4+U4),0)
A5: =DATE(B5,C5,1) -> 36647 | B5: 2000 | C5: 5 | D5: United States | E5: 19.614455 | F5: =(E5*1.8) +32 -> 67.306019 | G5: 1 | H5: 0.75 | I5: =_xlfn.NORM.INV(RAND(),LookupTables!$I$2,LookupTables!$I$3) -> 18.305718 | J5: =IF(AND(C5>=3,C5<=8),0,MAX(0,(100-F5)*LookupTables!$I$4*G5*H5+I5)) | K5: =ROUND(MAX(0,(F5-50)*LookupTables!$I$5*G5*H5+I5),0) | L5: =J5+K5 -> 0 | M5: =MAX(0,L5*(1+_xlfn.NORM.INV(RAND(),LookupTables!$I$6,0.08))) -> 0 | N5: =MIN(L5,M5) -> 0 | O5: =MAX(L5-M5,0) | P5: =MAX(M5-L5,0) | R5: =EDATE(R4,1) -> 41640 | S5: =MAX(0,_xlfn.FORECAST.ETS(R5,$E$2:$E$165,$A$2:$A$165,12)) -> 5.2387985 | T5: =IF(AND(MONTH(R5)>=3,MONTH(R5)<=8),0,MAX(0,(100-(S5*1.8+32))*LookupTables!$I$4*$G$2*INDEX(LookupTables!$F$2:$F$13,MATCH(MONTH(R5),LookupTables!$D$2:$D$13,0))+_xlfn.NORM.INV(RAND(),LookupTables!$I$2,LookupTables!$I$3))) | U5: =ROUND(MAX(0,((S5*1.8+32)-50)*LookupTables!$I$5*$G$2*INDEX(LookupTables!$F$2:$F$13,MATCH(MONTH(R5),LookupTables!$D$2:$D$13,0))+_xlfn.NORM.INV(RAND(),LookupTables!$I$2,LookupTables!$I$3)),0) | V5: =MAX(0,(T5+U5)*(1+_xlfn.NORM.INV(RAND(),LookupTables!$I$6,0.08))) -> #N/A | W5: =MIN(T5+U5,V5) -> #N/A | X5: =MAX((T5+U5)-V5,0) | Y5: =MAX(V5-(T5+U5),0)
A6: =DATE(B6,C6,1) -> 36678 | B6: 2000 | C6: 6 | D6: United States | E6: 22.743444 | F6: =(E6*1.8) +32 -> 72.938198 | G6: 1 | H6: 1.2 | I6: =_xlfn.NORM.INV(RAND(),LookupTables!$I$2,LookupTables!$I$3) -> 43.012522 | J6: =IF(AND(C6>=3,C6<=8),0,MAX(0,(100-F6)*LookupTables!$I$4*G6*H6+I6)) | K6: =ROUND(MAX(0,(F6-50)*LookupTables!$I$5*G6*H6+I6),0) | L6: =J6+K6 -> 0 | M6: =MAX(0,L6*(1+_xlfn.NORM.INV(RAND(),LookupTables!$I$6,0.08))) -> 0 | N6: =MIN(L6,M6) -> 0 | O6: =MAX(L6-M6,0) | P6: =MAX(M6-L6,0) | R6: =EDATE(R5,1) -> 41671 | S6: =MAX(0,_xlfn.FORECAST.ETS(R6,$E$2:$E$165,$A$2:$A$165,12)) -> 6.5325317 | T6: =IF(AND(MONTH(R6)>=3,MONTH(R6)<=8),0,MAX(0,(100-(S6*1.8+32))*LookupTables!$I$4*$G$2*INDEX(LookupTables!$F$2:$F$13,MATCH(MONTH(R6),LookupTables!$D$2:$D$13,0))+_xlfn.NORM.INV(RAND(),LookupTables!$I$2,LookupTables!$I$3))) | U6: =ROUND(MAX(0,((S6*1.8+32)-50)*LookupTables!$I$5*$G$2*INDEX(LookupTables!$F$2:$F$13,MATCH(MONTH(R6),LookupTables!$D$2:$D$13,0))+_xlfn.NORM.INV(RAND(),LookupTables!$I$2,LookupTables!$I$3)),0) | V6: =MAX(0,(T6+U6)*(1+_xlfn.NORM.INV(RAND(),LookupTables!$I$6,0.08))) -> #N/A | W6: =MIN(T6+U6,V6) -> #N/A | X6: =MAX((T6+U6)-V6,0) | Y6: =MAX(V6-(T6+U6),0)
A7: =DATE(B7,C7,1) -> 36708 | B7: 2000 | C7: 7 | D7: United States | E7: 24.178821 | F7: =(E7*1.8) +32 -> 75.521878 | G7: 1 | H7: 1.35 | I7: =_xlfn.NORM.INV(RAND(),LookupTables!$I$2,LookupTables!$I$3) -> -0.26334496 | J7: =IF(AND(C7>=3,C7<=8),0,MAX(0,(100-F7)*LookupTables!$I$4*G7*H7+I7)) | K7: =ROUND(MAX(0,(F7-50)*LookupTables!$I$5*G7*H7+I7),0) | L7: =J7+K7 -> 0 | M7: =MAX(0,L7*(1+_xlfn.NORM.INV(RAND(),LookupTables!$I$6,0.08))) -> 0 | N7: =MIN(L7,M7) -> 0 | O7: =MAX(L7-M7,0) | P7: =MAX(M7-L7,0) | R7: =EDATE(R6,1) -> 41699 | S7: =MAX(0,_xlfn.FORECAST.ETS(R7,$E$2:$E$165,$A$2:$A$165,12)) -> 9.8136817 | T7: =IF(AND(MONTH(R7)>=3,MONTH(R7)<=8),0,MAX(0,(100-(S7*1.8+32))*LookupTables!$I$4*$G$2*INDEX(LookupTables!$F$2:$F$13,MATCH(MONTH(R7),LookupTables!$D$2:$D$13,0))+_xlfn.NORM.INV(RAND(),LookupTables!$I$2,LookupTables!$I$3))) | U7: =ROUND(MAX(0,((S7*1.8+32)-50)*LookupTables!$I$5*$G$2*INDEX(LookupTables!$F$2:$F$13,MATCH(MONTH(R7),LookupTables!$D$2:$D$13,0))+_xlfn.NORM.INV(RAND(),LookupTables!$I$2,LookupTables!$I$3)),0) | V7: =MAX(0,(T7+U7)*(1+_xlfn.NORM.INV(RAND(),LookupTables!$I$6,0.08))) -> #N/A | W7: =MIN(T7+U7,V7) -> #N/A | X7: =MAX((T7+U7)-V7,0) | Y7: =MAX(V7-(T7+U7),0)
A8: =DATE(B8,C8,1) -> 36739 | B8: 2000 | C8: 8 | D8: United States | E8: 24.63272 | F8: =(E8*1.8) +32 -> 76.338896 | G8: 1 | H8: 1.25 | I8: =_xlfn.NORM.INV(RAND(),LookupTables!$I$2,LookupTables!$I$3) -> -49.074115 | J8: =IF(AND(C8>=3,C8<=8),0,MAX(0,(100-F8)*LookupTables!$I$4*G8*H8+I8)) | K8: =ROUND(MAX(0,(F8-50)*LookupTables!$I$5*G8*H8+I8),0) | L8: =J8+K8 -> 0 | M8: =MAX(0,L8*(1+_xlfn.NORM.INV(RAND(),LookupTables!$I$6,0.08))) -> 0 | N8: =MIN(L8,M8) -> 0 | O8: =MAX(L8-M8,0) | P8: =MAX(M8-L8,0) | R8: =EDATE(R7,1) -> 41730 | S8: =MAX(0,_xlfn.FORECAST.ETS(R8,$E$2:$E$165,$A$2:$A$165,12)) -> 14.372633 | T8: =IF(AND(MONTH(R8)>=3,MONTH(R8)<=8),0,MAX(0,(100-(S8*1.8+32))*LookupTables!$I$4*$G$2*INDEX(LookupTables!$F$2:$F$13,MATCH(MONTH(R8),LookupTables!$D$2:$D$13,0))+_xlfn.NORM.INV(RAND(),LookupTables!$I$2,LookupTables!$I$3))) | U8: =ROUND(MAX(0,((S8*1.8+32)-50)*LookupTables!$I$5*$G$2*INDEX(LookupTables!$F$2:$F$13,MATCH(MONTH(R8),LookupTables!$D$2:$D$13,0))+_xlfn.NORM.INV(RAND(),LookupTables!$I$2,LookupTables!$I$3)),0) | V8: =MAX(0,(T8+U8)*(1+_xlfn.NORM.INV(RAND(),LookupTables!$I$6,0.08))) -> #N/A | W8: =MIN(T8+U8,V8) -> #N/A | X8: =MAX((T8+U8)-V8,0) | Y8: =MAX(V8-(T8+U8),0)
A9: =DATE(B9,C9,1) -> 36770 | B9: 2000 | C9: 9 | D9: United States | E9: 21.316576 | F9: =(E9*1.8) +32 -> 70.369837 | G9: 1 | H9: 0.8 | I9: =_xlfn.NORM.INV(RAND(),LookupTables!$I$2,LookupTables!$I$3) -> 96.884409 | J9: =IF(AND(C9>=3,C9<=8),0,MAX(0,(100-F9)*LookupTables!$I$4*G9*H9+I9)) | K9: =ROUND(MAX(0,(F9-50)*LookupTables!$I$5*G9*H9+I9),0) | L9: =J9+K9 -> 411.61811 | M9: =MAX(0,L9*(1+_xlfn.NORM.INV(RAND(),LookupTables!$I$6,0.08))) -> 476.59801 | N9: =MIN(L9,M9) -> 411.61811 | O9: =MAX(L9-M9,0) | P9: =MAX(M9-L9,0) | R9: =EDATE(R8,1) -> 41760 | S9: =MAX(0,_xlfn.FORECAST.ETS(R9,$E$2:$E$165,$A$2:$A$165,12)) -> 18.75905 | T9: =IF(AND(MONTH(R9)>=3,MONTH(R9)<=8),0,MAX(0,(100-(S9*1.8+32))*LookupTables!$I$4*$G$2*INDEX(LookupTables!$F$2:$F$13,MATCH(MONTH(R9),LookupTables!$D$2:$D$13,0))+_xlfn.NORM.INV(RAND(),LookupTables!$I$2,LookupTables!$I$3))) | U9: =ROUND(MAX(0,((S9*1.8+32)-50)*LookupTables!$I$5*$G$2*INDEX(LookupTables!$F$2:$F$13,MATCH(MONTH(R9),LookupTables!$D$2:$D$13,0))+_xlfn.NORM.INV(RAND(),LookupTables!$I$2,LookupTables!$I$3)),0) | V9: =MAX(0,(T9+U9)*(1+_xlfn.NORM.INV(RAND(),LookupTables!$I$6,0.08))) -> #N/A | W9: =MIN(T9+U9,V9) -> #N/A | X9: =MAX((T9+U9)-V9,0) | Y9: =MAX(V9-(T9+U9),0)
A10: =DATE(B10,C10,1) -> 36800 | B10: 2000 | C10: 10 | D10: United States | E10: 15.800961 | F10: =(E10*1.8) +32 -> 60.44173 | G10: 1 | H10: 0.85 | I10: =_xlfn.NORM.INV(RAND(),LookupTables!$I$2,LookupTables!$I$3) -> -74.894001 | J10: =IF(AND(C10>=3,C10<=8),0,MAX(0,(100-F10)*LookupTables!$I$4*G10*H10+I10)) | K10: =ROUND(MAX(0,(F10-50)*LookupTables!$I$5*G10*H10+I10),0) | L10: =J10+K10 -> 282.95191 | M10: =MAX(0,L10*(1+_xlfn.NORM.INV(RAND(),LookupTables!$I$6,0.08))) -> 316.93114 | N10: =MIN(L10,M10) -> 282.95191 | O10: =MAX(L10-M10,0) | P10: =MAX(M10-L10,0) | R10: =EDATE(R9,1) -> 41791 | S10: =MAX(0,_xlfn.FORECAST.ETS(R10,$E$2:$E$165,$A$2:$A$165,12)) -> 22.730634 | T10: =IF(AND(MONTH(R10)>=3,MONTH(R10)<=8),0,MAX(0,(100-(S10*1.8+32))*LookupTables!$I$4*$G$2*INDEX(LookupTables!$F$2:$F$13,MATCH(MONTH(R10),LookupTables!$D$2:$D$13,0))+_xlfn.NORM.INV(RAND(),LookupTables!$I$2,LookupTables!$I$3))) | U10: =ROUND(MAX(0,((S10*1.8+32)-50)*LookupTables!$I$5*$G$2*INDEX(LookupTables!$F$2:$F$13,MATCH(MONTH(R10),LookupTables!$D$2:$D$13,0))+_xlfn.NORM.INV(RAND(),LookupTables!$I$2,LookupTables!$I$3)),0) | V10: =MAX(0,(T10+U10)*(1+_xlfn.NORM.INV(RAND(),LookupTables!$I$6,0.08))) -> #N/A | W10: =MIN(T10+U10,V10) -> #N/A | X10: =MAX((T10+U10)-V10,0) | Y10: =MAX(V10-(T10+U10),0)
A11: =DATE(B11,C11,1) -> 36831 | B11: 2000 | C11: 11 | D11: United States | E11: 8.5155603 | F11: =(E11*1.8) +32 -> 47.328009 | G11: 1 | H11: 1 | I11: =_xlfn.NORM.INV(RAND(),LookupTables!$I$2,LookupTables!$I$3) -> -51.730563 | J11: =IF(AND(C11>=3,C11<=8),0,MAX(0,(100-F11)*LookupTables!$I$4*G11*H11+I11)) | K11: =ROUND(MAX(0,(F11-50)*LookupTables!$I$5*G11*H11+I11),0) | L11: =J11+K11 -> 405.69164 | M11: =MAX(0,L11*(1+_xlfn.NORM.INV(RAND(),LookupTables!$I$6,0.08))) -> 470.04115 | N11: =MIN(L11,M11) -> 405.69164 | O11: =MAX(L11-M11,0) | P11: =MAX(M11-L11,0) | R11: =EDATE(R10,1) -> 41821 | S11: =MAX(0,_xlfn.FORECAST.ETS(R11,$E$2:$E$165,$A$2:$A$165,12)) -> 24.818394 | T11: =IF(AND(MONTH(R11)>=3,MONTH(R11)<=8),0,MAX(0,(100-(S11*1.8+32))*LookupTables!$I$4*$G$2*INDEX(LookupTables!$F$2:$F$13,MATCH(MONTH(R11),LookupTables!$D$2:$D$13,0))+_xlfn.NORM.INV(RAND(),LookupTables!$I$2,LookupTables!$I$3))) | U11: =ROUND(MAX(0,((S11*1.8+32)-50)*LookupTables!$I$5*$G$2*INDEX(LookupTables!$F$2:$F$13,MATCH(MONTH(R11),LookupTables!$D$2:$D$13,0))+_xlfn.NORM.INV(RAND(),LookupTables!$I$2,LookupTables!$I$3)),0) | V11: =MAX(0,(T11+U11)*(1+_xlfn.NORM.INV(RAND(),LookupTables!$I$6,0.08))) -> #N/A | W11: =MIN(T11+U11,V11) -> #N/A | X11: =MAX((T11+U11)-V11,0) | Y11: =MAX(V11-(T11+U11),0)
A12: =DATE(B12,C12,1) -> 36861 | B12: 2000 | C12: 12 | D12: United States | E12: 3.7005603 | F12: =(E12*1.8) +32 -> 38.661009 | G12: 1 | H12: 1.4 | I12: =_xlfn.NORM.INV(RAND(),LookupTables!$I$2,LookupTables!$I$3) -> -40.867089 | J12: =IF(AND(C12>=3,C12<=8),0,MAX(0,(100-F12)*LookupTables!$I$4*G12*H12+I12)) | K12: =ROUND(MAX(0,(F12-50)*LookupTables!$I$5*G12*H12+I12),0) | L12: =J12+K12 -> 633.22899 | M12: =MAX(0,L12*(1+_xlfn.NORM.INV(RAND(),LookupTables!$I$6,0.08))) -> 675.71375 | N12: =MIN(L12,M12) -> 633.22899 | O12: =MAX(L12-M12,0) | P12: =MAX(M12-L12,0) | R12: =EDATE(R11,1) -> 41852 | S12: =MAX(0,_xlfn.FORECAST.ETS(R12,$E$2:$E$165,$A$2:$A$165,12)) -> 24.901512 | T12: =IF(AND(MONTH(R12)>=3,MONTH(R12)<=8),0,MAX(0,(100-(S12*1.8+32))*LookupTables!$I$4*$G$2*INDEX(LookupTables!$F$2:$F$13,MATCH(MONTH(R12),LookupTables!$D$2:$D$13,0))+_xlfn.NORM.INV(RAND(),LookupTables!$I$2,LookupTables!$I$3))) | U12: =ROUND(MAX(0,((S12*1.8+32)-50)*LookupTables!$I$5*$G$2*INDEX(LookupTables!$F$2:$F$13,MATCH(MONTH(R12),LookupTables!$D$2:$D$13,0))+_xlfn.NORM.INV(RAND(),LookupTables!$I$2,LookupTables!$I$3)),0) | V12: =MAX(0,(T12+U12)*(1+_xlfn.NORM.INV(RAND(),LookupTables!$I$6,0.08))) -> #N/A | W12: =MIN(T12+U12,V12) -> #N/A | X12: =MAX((T12+U12)-V12,0) | Y12: =MAX(V12-(T12+U12),0)
A13: =DATE(B13,C13,1) -> 36892 | B13: 2001 | C13: 1 | D13: United States | E13: 4.0248327 | F13: =(E13*1.8) +32 -> 39.244699 | G13: 1 | H13: 1.3 | I13: =_xlfn.NORM.INV(RAND(),LookupTables!$I$2,LookupTables!$I$3) -> 37.590499 | J13: =IF(AND(C13>=3,C13<=8),0,MAX(0,(100-F13)*LookupTables!$I$4*G13*H13+I13)) | K13: =ROUND(MAX(0,(F13-50)*LookupTables!$I$5*G13*H13+I13),0) | L13: =J13+K13 -> 661.42909 | M13: =MAX(0,L13*(1+_xlfn.NORM.INV(RAND(),LookupTables!$I$6,0.08))) -> 707.03495 | N13: =MIN(L13,M13) -> 661.42909 | O13: =MAX(L13-M13,0) | P13: =MAX(M13-L13,0) | R13: =EDATE(R12,1) -> 41883 | S13: =MAX(0,_xlfn.FORECAST.ETS(R13,$E$2:$E$165,$A$2:$A$165,12)) -> 21.687078 | T13: =IF(AND(MONTH(R13)>=3,MONTH(R13)<=8),0,MAX(0,(100-(S13*1.8+32))*LookupTables!$I$4*$G$2*INDEX(LookupTables!$F$2:$F$13,MATCH(MONTH(R13),LookupTables!$D$2:$D$13,0))+_xlfn.NORM.INV(RAND(),LookupTables!$I$2,LookupTables!$I$3))) | U13: =ROUND(MAX(0,((S13*1.8+32)-50)*LookupTables!$I$5*$G$2*INDEX(LookupTables!$F$2:$F$13,MATCH(MONTH(R13),LookupTables!$D$2:$D$13,0))+_xlfn.NORM.INV(RAND(),LookupTables!$I$2,LookupTables!$I$3)),0) | V13: =MAX(0,(T13+U13)*(1+_xlfn.NORM.INV(RAND(),LookupTables!$I$6,0.08))) -> #N/A | W13: =MIN(T13+U13,V13) -> #N/A | X13: =MAX((T13+U13)-V13,0) | Y13: =MAX(V13-(T13+U13),0)
A14: =DATE(B14,C14,1) -> 36923 | B14: 2001 | C14: 2 | D14: United States | E14: 6.3833891 | F14: =(E14*1.8) +32 -> 43.4901 | G14: 1 | H14: 1.25 | I14: =_xlfn.NORM.INV(RAND(),LookupTables!$I$2,LookupTables!$I$3) -> -2.6435296 | J14: =IF(AND(C14>=3,C14<=8),0,MAX(0,(100-F14)*LookupTables!$I$4*G14*H14+I14)) | K14: =ROUND(MAX(0,(F14-50)*LookupTables!$I$5*G14*H14+I14),0) | L14: =J14+K14 -> 582.46029 | M14: =MAX(0,L14*(1+_xlfn.NORM.INV(RAND(),LookupTables!$I$6,0.08))) -> 755.52652 | N14: =MIN(L14,M14) -> 582.46029 | O14: =MAX(L14-M14,0) | P14: =MAX(M14-L14,0) | R14: =EDATE(R13,1) -> 41913 | S14: =MAX(0,_xlfn.FORECAST.ETS(R14,$E$2:$E$165,$A$2:$A$165,12)) -> 15.821135 | T14: =IF(AND(MONTH(R14)>=3,MONTH(R14)<=8),0,MAX(0,(100-(S14*1.8+32))*LookupTables!$I$4*$G$2*INDEX(LookupTables!$F$2:$F$13,MATCH(MONTH(R14),LookupTables!$D$2:$D$13,0))+_xlfn.NORM.INV(RAND(),LookupTables!$I$2,LookupTables!$I$3))) | U14: =ROUND(MAX(0,((S14*1.8+32)-50)*LookupTables!$I$5*$G$2*INDEX(LookupTables!$F$2:$F$13,MATCH(MONTH(R14),LookupTables!$D$2:$D$13,0))+_xlfn.NORM.INV(RAND(),LookupTables!$I$2,LookupTables!$I$3)),0) | V14: =MAX(0,(T14+U14)*(1+_xlfn.NORM.INV(RAND(),LookupTables!$I$6,0.08))) -> #N/A | W14: =MIN(T14+U14,V14) -> #N/A | X14: =MAX((T14+U14)-V14,0) | Y14: =MAX(V14-(T14+U14),0)
... A165: =DATE(B165,C165,1) -> 41518 | B165: 2013 | C165: 9 | D165: United States | E165: 22.339172 | F165: =(E165*1.8) +32 -> 72.210509 | G165: 1 | H165: 0.8 | I165: =_xlfn.NORM.INV(RAND(),LookupTables!$I$2,LookupTables!$I$3) -> 15.854892 | J165: =IF(AND(C165>=3,C165<=8),0,MAX(0,(100-F165)*LookupTables!$I$4*G165*H165+I165)) | K165: =ROUND(MAX(0,(F165-50)*LookupTables!$I$5*G165*H165+I165),0) | L165: =J165+K165 -> 326.4982 | M165: =MAX(0,L165*(1+_xlfn.NORM.INV(RAND(),LookupTables!$I$6,0.08))) -> 364.31983 | N165: =MIN(L165,M165) -> 326.4982 | O165: =MAX(L165-M165,0) | P165: =MAX(M165-L165,0) | R165: =EDATE(R164,1) -> 46508 | S165: =MAX(0,_xlfn.FORECAST.ETS(R165,$E$2:$E$165,$A$2:$A$165,12)) -> 18.344862 | T165: =IF(AND(MONTH(R165)>=3,MONTH(R165)<=8),0,MAX(0,(100-(S165*1.8+32))*LookupTables!$I$4*$G$2*INDEX(LookupTables!$F$2:$F$13,MATCH(MONTH(R165),LookupTables!$D$2:$D$13,0))+_xlfn.NORM.INV(RAND(),LookupTables!$I$2,LookupTables!$I$3))) | U165: =ROUND(MAX(0,((S165*1.8+32)-50)*LookupTables!$I$5*$G$2*INDEX(LookupTables!$F$2:$F$13,MATCH(MONTH(R165),LookupTables!$D$2:$D$13,0))+_xlfn.NORM.INV(RAND(),LookupTables!$I$2,LookupTables!$I$3)),0) | V165: =MAX(0,(T165+U165)*(1+_xlfn.NORM.INV(RAND(),LookupTables!$I$6,0.08))) -> #N/A | W165: =MIN(T165+U165,V165) -> #N/A | X165: =MAX((T165+U165)-V165,0) | Y165: =MAX(V165-(T165+U165),0)

Sheet Sheet2

Sheet Solver
A1: Date | B1: Country | C1: Temp_F | D1: Month | E1: Year | F1: CountryFactor | G1: SeasonFactor | H1: Noise | I1: Winter_Demand | J1: Summer_Demand | K1: Total_Demand | L1: Inventory | M1: Sales | N1: Lost_Sales | O1: Excess_Inventory
A2: 45292 | B2: USA | C2: 31.3 | D2: =MONTH(A2) -> 1 | E2: =YEAR(A2) -> 2024 | F2: =VLOOKUP(B2,LookupTables!$A$2:$B$8,2,FALSE) -> 1 | G2: =INDEX(LookupTables!$F$2:$F$13,MATCH(D2,LookupTables!$D$2:$D$13,0)) -> 1.3 | H2: =_xlfn.NORM.INV(RAND(),LookupTables!$I$2,LookupTables!$I$3) -> -32.976864 | I2: =MAX(0,(100-C2)*LookupTables!$I$4*F2*G2+H2) -> 413.57314 | J2: =MAX(0,(C2-50)*LookupTables!$I$5*F2*G2+H2) -> 0 | K2: =I2+J2 -> 413.57314 | L2: =MAX(0,K2*(1+_xlfn.NORM.INV(RAND(),LookupTables!$I$6,0.08))) -> 453.04936 | M2: =MIN(K2,L2) -> 413.57314 | N2: =MAX(0,K2-L2) -> 0 | O2: =MAX(0,L2-K2) -> 39.476229
A3: 45299 | B3: Canada | C3: 14.1 | D3: =MONTH(A3) -> 1 | E3: =YEAR(A3) -> 2024 | F3: =VLOOKUP(B3,LookupTables!$A$2:$B$8,2,FALSE) -> 1.2 | G3: =INDEX(LookupTables!$F$2:$F$13,MATCH(D3,LookupTables!$D$2:$D$13,0)) -> 1.3 | H3: =_xlfn.NORM.INV(RAND(),LookupTables!$I$2,LookupTables!$I$3) -> 6.7059773 | I3: =MAX(0,(100-C3)*LookupTables!$I$4*F3*G3+H3) -> 676.72598 | J3: =MAX(0,(C3-50)*LookupTables!$I$5*F3*G3+H3) -> 0 | K3: =I3+J3 -> 676.72598 | L3: =MAX(0,K3*(1+_xlfn.NORM.INV(RAND(),LookupTables!$I$6,0.08))) -> 805.63231 | M3: =MIN(K3,L3) -> 676.72598 | N3: =MAX(0,K3-L3) -> 0 | O3: =MAX(0,L3-K3) -> 128.90633
A4: 45306 | B4: UK | C4: 39.4 | D4: =MONTH(A4) -> 1 | E4: =YEAR(A4) -> 2024 | F4: =VLOOKUP(B4,LookupTables!$A$2:$B$8,2,FALSE) -> 0.9 | G4: =INDEX(LookupTables!$F$2:$F$13,MATCH(D4,LookupTables!$D$2:$D$13,0)) -> 1.3 | H4: =_xlfn.NORM.INV(RAND(),LookupTables!$I$2,LookupTables!$I$3) -> -20.181733 | I4: =MAX(0,(100-C4)*LookupTables!$I$4*F4*G4+H4) -> 334.32827 | J4: =MAX(0,(C4-50)*LookupTables!$I$5*F4*G4+H4) -> 0 | K4: =I4+J4 -> 334.32827 | L4: =MAX(0,K4*(1+_xlfn.NORM.INV(RAND(),LookupTables!$I$6,0.08))) -> 368.77586 | M4: =MIN(K4,L4) -> 334.32827 | N4: =MAX(0,K4-L4) -> 0 | O4: =MAX(0,L4-K4) -> 34.447597
A5: 45313 | B5: Germany | C5: 36.5 | D5: =MONTH(A5) -> 1 | E5: =YEAR(A5) -> 2024 | F5: =VLOOKUP(B5,LookupTables!$A$2:$B$8,2,FALSE) -> 1.1 | G5: =INDEX(LookupTables!$F$2:$F$13,MATCH(D5,LookupTables!$D$2:$D$13,0)) -> 1.3 | H5: =_xlfn.NORM.INV(RAND(),LookupTables!$I$2,LookupTables!$I$3) -> 7.4877865 | I5: =MAX(0,(100-C5)*LookupTables!$I$4*F5*G5+H5) -> 461.51279 | J5: =MAX(0,(C5-50)*LookupTables!$I$5*F5*G5+H5) -> 0 | K5: =I5+J5 -> 461.51279 | L5: =MAX(0,K5*(1+_xlfn.NORM.INV(RAND(),LookupTables!$I$6,0.08))) -> 473.87208 | M5: =MIN(K5,L5) -> 461.51279 | N5: =MAX(0,K5-L5) -> 0 | O5: =MAX(0,L5-K5) -> 12.359293
A6: 45320 | B6: Australia | C6: 78.4 | D6: =MONTH(A6) -> 1 | E6: =YEAR(A6) -> 2024 | F6: =VLOOKUP(B6,LookupTables!$A$2:$B$8,2,FALSE) -> 0.85 | G6: =INDEX(LookupTables!$F$2:$F$13,MATCH(D6,LookupTables!$D$2:$D$13,0)) -> 1.3 | H6: =_xlfn.NORM.INV(RAND(),LookupTables!$I$2,LookupTables!$I$3) -> -73.380258 | I6: =MAX(0,(100-C6)*LookupTables!$I$4*F6*G6+H6) -> 45.959742 | J6: =MAX(0,(C6-50)*LookupTables!$I$5*F6*G6+H6) -> 83.529742 | K6: =I6+J6 -> 129.48948 | L6: =MAX(0,K6*(1+_xlfn.NORM.INV(RAND(),LookupTables!$I$6,0.08))) -> 146.17373 | M6: =MIN(K6,L6) -> 129.48948 | N6: =MAX(0,K6-L6) -> 0 | O6: =MAX(0,L6-K6) -> 16.684247
A7: 45327 | B7: Japan | C7: 36.5 | D7: =MONTH(A7) -> 2 | E7: =YEAR(A7) -> 2024 | F7: =VLOOKUP(B7,LookupTables!$A$2:$B$8,2,FALSE) -> 1.05 | G7: =INDEX(LookupTables!$F$2:$F$13,MATCH(D7,LookupTables!$D$2:$D$13,0)) -> 1.25 | H7: =_xlfn.NORM.INV(RAND(),LookupTables!$I$2,LookupTables!$I$3) -> -21.122041 | I7: =MAX(0,(100-C7)*LookupTables!$I$4*F7*G7+H7) -> 395.59671 | J7: =MAX(0,(C7-50)*LookupTables!$I$5*F7*G7+H7) -> 0 | K7: =I7+J7 -> 395.59671 | L7: =MAX(0,K7*(1+_xlfn.NORM.INV(RAND(),LookupTables!$I$6,0.08))) -> 414.46807 | M7: =MIN(K7,L7) -> 395.59671 | N7: =MAX(0,K7-L7) -> 0 | O7: =MAX(0,L7-K7) -> 18.871359
A8: 45334 | B8: Brazil | C8: 82.7 | D8: =MONTH(A8) -> 2 | E8: =YEAR(A8) -> 2024 | F8: =VLOOKUP(B8,LookupTables!$A$2:$B$8,2,FALSE) -> 0.7 | G8: =INDEX(LookupTables!$F$2:$F$13,MATCH(D8,LookupTables!$D$2:$D$13,0)) -> 1.25 | H8: =_xlfn.NORM.INV(RAND(),LookupTables!$I$2,LookupTables!$I$3) -> -101.38848 | I8: =MAX(0,(100-C8)*LookupTables!$I$4*F8*G8+H8) -> 0 | J8: =MAX(0,(C8-50)*LookupTables!$I$5*F8*G8+H8) -> 41.674016 | K8: =I8+J8 -> 41.674016 | L8: =MAX(0,K8*(1+_xlfn.NORM.INV(RAND(),LookupTables!$I$6,0.08))) -> 40.201256 | M8: =MIN(K8,L8) -> 40.201256 | N8: =MAX(0,K8-L8) -> 1.4727602 | O8: =MAX(0,L8-K8) -> 0
A9: 45341 | B9: USA | C9: 33.7 | D9: =MONTH(A9) -> 2 | E9: =YEAR(A9) -> 2024 | F9: =VLOOKUP(B9,LookupTables!$A$2:$B$8,2,FALSE) -> 1 | G9: =INDEX(LookupTables!$F$2:$F$13,MATCH(D9,LookupTables!$D$2:$D$13,0)) -> 1.25 | H9: =_xlfn.NORM.INV(RAND(),LookupTables!$I$2,LookupTables!$I$3) -> 35.219136 | I9: =MAX(0,(100-C9)*LookupTables!$I$4*F9*G9+H9) -> 449.59414 | J9: =MAX(0,(C9-50)*LookupTables!$I$5*F9*G9+H9) -> 0 | K9: =I9+J9 -> 449.59414 | L9: =MAX(0,K9*(1+_xlfn.NORM.INV(RAND(),LookupTables!$I$6,0.08))) -> 406.98936 | M9: =MIN(K9,L9) -> 406.98936 | N9: =MAX(0,K9-L9) -> 42.604772 | O9: =MAX(0,L9-K9) -> 0
A10: 45348 | B10: Canada | C10: 16.9 | D10: =MONTH(A10) -> 2 | E10: =YEAR(A10) -> 2024 | F10: =VLOOKUP(B10,LookupTables!$A$2:$B$8,2,FALSE) -> 1.2 | G10: =INDEX(LookupTables!$F$2:$F$13,MATCH(D10,LookupTables!$D$2:$D$13,0)) -> 1.25 | H10: =_xlfn.NORM.INV(RAND(),LookupTables!$I$2,LookupTables!$I$3) -> 4.2879323 | I10: =MAX(0,(100-C10)*LookupTables!$I$4*F10*G10+H10) -> 627.53793 | J10: =MAX(0,(C10-50)*LookupTables!$I$5*F10*G10+H10) -> 0 | K10: =I10+J10 -> 627.53793 | L10: =MAX(0,K10*(1+_xlfn.NORM.INV(RAND(),LookupTables!$I$6,0.08))) -> 563.36912 | M10: =MIN(K10,L10) -> 563.36912 | N10: =MAX(0,K10-L10) -> 64.168816 | O10: =MAX(0,L10-K10) -> 0
A11: 45355 | B11: UK | C11: 45.6 | D11: =MONTH(A11) -> 3 | E11: =YEAR(A11) -> 2024 | F11: =VLOOKUP(B11,LookupTables!$A$2:$B$8,2,FALSE) -> 0.9 | G11: =INDEX(LookupTables!$F$2:$F$13,MATCH(D11,LookupTables!$D$2:$D$13,0)) -> 0.8 | H11: =_xlfn.NORM.INV(RAND(),LookupTables!$I$2,LookupTables!$I$3) -> -16.556653 | I11: =MAX(0,(100-C11)*LookupTables!$I$4*F11*G11+H11) -> 179.28335 | J11: =MAX(0,(C11-50)*LookupTables!$I$5*F11*G11+H11) -> 0 | K11: =I11+J11 -> 179.28335 | L11: =MAX(0,K11*(1+_xlfn.NORM.INV(RAND(),LookupTables!$I$6,0.08))) -> 179.80228 | M11: =MIN(K11,L11) -> 179.28335 | N11: =MAX(0,K11-L11) -> 0 | O11: =MAX(0,L11-K11) -> 0.51893262
A12: 45362 | B12: Germany | C12: 44.2 | D12: =MONTH(A12) -> 3 | E12: =YEAR(A12) -> 2024 | F12: =VLOOKUP(B12,LookupTables!$A$2:$B$8,2,FALSE) -> 1.1 | G12: =INDEX(LookupTables!$F$2:$F$13,MATCH(D12,LookupTables!$D$2:$D$13,0)) -> 0.8 | H12: =_xlfn.NORM.INV(RAND(),LookupTables!$I$2,LookupTables!$I$3) -> 101.64089 | I12: =MAX(0,(100-C12)*LookupTables!$I$4*F12*G12+H12) -> 347.16089 | J12: =MAX(0,(C12-50)*LookupTables!$I$5*F12*G12+H12) -> 76.120888 | K12: =I12+J12 -> 423.28178 | L12: =MAX(0,K12*(1+_xlfn.NORM.INV(RAND(),LookupTables!$I$6,0.08))) -> 453.25757 | M12: =MIN(K12,L12) -> 423.28178 | N12: =MAX(0,K12-L12) -> 0 | O12: =MAX(0,L12-K12) -> 29.975788
A13: 45369 | B13: Australia | C13: 79.8 | D13: =MONTH(A13) -> 3 | E13: =YEAR(A13) -> 2024 | F13: =VLOOKUP(B13,LookupTables!$A$2:$B$8,2,FALSE) -> 0.85 | G13: =INDEX(LookupTables!$F$2:$F$13,MATCH(D13,LookupTables!$D$2:$D$13,0)) -> 0.8 | H13: =_xlfn.NORM.INV(RAND(),LookupTables!$I$2,LookupTables!$I$3) -> -15.384176 | I13: =MAX(0,(100-C13)*LookupTables!$I$4*F13*G13+H13) -> 53.295824 | J13: =MAX(0,(C13-50)*LookupTables!$I$5*F13*G13+H13) -> 85.935824 | K13: =I13+J13 -> 139.23165 | L13: =MAX(0,K13*(1+_xlfn.NORM.INV(RAND(),LookupTables!$I$6,0.08))) -> 154.08608 | M13: =MIN(K13,L13) -> 139.23165 | N13: =MAX(0,K13-L13) -> 0 | O13: =MAX(0,L13-K13) -> 14.854429
... A105: 46013 | B105: Japan | C105: 39.4 | D105: =MONTH(A105) -> 12 | E105: =YEAR(A105) -> 2025 | F105: =VLOOKUP(B105,LookupTables!$A$2:$B$8,2,FALSE) -> 1.05 | G105: =INDEX(LookupTables!$F$2:$F$13,MATCH(D105,LookupTables!$D$2:$D$13,0)) -> 1.4 | H105: =_xlfn.NORM.INV(RAND(),LookupTables!$I$2,LookupTables!$I$3) -> -27.540673 | I105: =MAX(0,(100-C105)*LookupTables!$I$4*F105*G105+H105) -> 417.86933 | J105: =MAX(0,(C105-50)*LookupTables!$I$5*F105*G105+H105) -> 0 | K105: =I105+J105 -> 417.86933 | L105: =MAX(0,K105*(1+_xlfn.NORM.INV(RAND(),LookupTables!$I$6,0.08))) -> 495.92891 | M105: =MIN(K105,L105) -> 417.86933 | N105: =MAX(0,K105-L105) -> 0 | O105: =MAX(0,L105-K105) -> 78.059586

Sheet FormulaReference
A1: Column | B1: Name | C1: Excel Formula (Row 2) | D1: Explanation
A2: A | B2: Date | C2: (raw input) | D2: Weekly dates starting 2024-01-01
A3: B | B3: Country | C3: (raw input) | D3: One of 7 countries from lookup table
A4: C | B4: Temp_F | C4: (raw input) | D4: Temperature in °F with ±5° random variation
A5: D | B5: Month | C5: =MONTH(A2) | D5: Extracts month number from Date
A6: E | B6: Year | C6: =YEAR(A2) | D6: Extracts year from Date
A7: F | B7: CountryFactor | C7: =VLOOKUP(B2,LookupTables!$A$2:$B$8,2,FALSE) | D7: Market-size multiplier per country
A8: G | B8: SeasonFactor | C8: =INDEX(LookupTables!$F$2:$F$13,MATCH(D2,LookupTables!$D$2:$D$13,0)) | D8: Seasonal demand multiplier (high in winter & summer)
A9: H | B9: Noise | C9: =@NORM.INV(RAND(), LookupTables!$I$2, LookupTables!$I$3) | D9: Random noise ~ N(0, 50) for realism
A10: I | B10: Winter_Demand | C10: =MAX(0,(100-C2)*LookupTables!$I$4*F2*G2+H2) | D10: Rises as temp falls below 100°F; scaled by country & season
A11: J | B11: Summer_Demand | C11: =MAX(0,(C2-50)*LookupTables!$I$5*F2*G2+H2) | D11: Rises as temp exceeds 50°F; scaled by country & season
A12: K | B12: Total_Demand | C12: =I2+J2 | D12: Combined winter + summer apparel demand
... A16: O | B16: Excess_Inventory | C16: =MAX(0,L2-K2) | D16: Overstock (markdown/waste cost driver)
A19: TIPS & NEXT STEPS
A21: 1. FREEZE RANDOMNESS: Select columns H & L → Copy → Paste Special → Values Only.
A22: This locks Noise and Inventory so they don't recalculate on every edit.
A24: 2. EXTEND DATA: Copy the last data row down. Formulas auto-adjust. Only change A (Date), B (Country), C (Temp).
A26: 3. PIVOT TABLE: Insert → PivotTable on the Data sheet. Drag Country to Rows, Month to Columns, SUM of Sales to Values.
A28: 4. FORECASTING (Excel built-in): Select Date (col A) & Total_Demand (col K) → Insert → Forecast Sheet.
A30: 5. SOLVER OPTIMIZATION:
A31: a. Decision variable: Inventory buffer % (cell LookupTables!I6, currently 10%)
A32: b. Objective: Minimize total cost = Lost_Sales×StockoutCost + Excess_Inventory×HoldingCost
A33: c. Add a Cost sheet: StockoutCostPerUnit (e.g. $15), HoldingCostPerUnit (e.g. $3)
A34: d. TotalCost cell = SUMPRODUCT(Lost_Sales, StockoutCost) + SUMPRODUCT(Excess, HoldingCost)
A35: e. Data → Solver → Set Objective = TotalCost, By Changing = Buffer%, Minimize
A37: 6. SCENARIO ANALYSIS: Use Data → What-If → Data Table to vary InvBufferPct and see cost impact.

Sheet Sheet3
B2: IMPORTANT DETAIL
B3: You inserted a recommendation that uses a PivotTable.
B4: PivotTables work best when the data is organized in columns and have a single header row, so we did that below.
C6: Date | D6: Year | E6: Month | F6: Country | G6: AvgTemp (C) | H6: AvgTemp (F) | I6: CountryFactor | J6: SeasonFactor | K6: Noise | L6: Winter_Demand | M6: Summer_Demand | N6: Total_Demand | O6: Inventory | P6: Sales | Q6: Lost_Sales | R6: Excess_Inventory | S6: Field17
D7: 2000 | E7: 2 | F7: Denmark | G7: 3.6475 | H7: 38.5655 | J7: #N/A | K7: #N/A | L7: -108.21021 | M7: #N/A | N7: #N/A | O7: #N/A | P7: #N/A | Q7: #N/A | R7: #N/A | S7: #N/A
D8: 2000 | E8: 3 | F8: Denmark | G8: 4.0005 | H8: 39.2009 | J8: #N/A | K8: #N/A | L8: 12.773368 | M8: #N/A | N8: #N/A | O8: #N/A | P8: #N/A | Q8: #N/A | R8: #N/A | S8: #N/A
D9: 2000 | E9: 4 | F9: Denmark | G9: 8.4615 | H9: 47.2307 | J9: #N/A | K9: #N/A | L9: 2.1136371 | M9: #N/A | N9: #N/A | O9: #N/A | P9: #N/A | Q9: #N/A | R9: #N/A | S9: #N/A
D10: 2000 | E10: 5 | F10: Denmark | G10: 13.6475 | H10: 56.5655 | J10: #N/A | K10: #N/A | L10: -52.405198 | M10: #N/A | N10: #N/A | O10: #N/A | P10: #N/A | Q10: #N/A | R10: #N/A | S10: #N/A
D11: 2000 | E11: 6 | F11: Denmark | G11: 15.002 | H11: 59.0036 | J11: #N/A | K11: #N/A | L11: -43.10402 | M11: #N/A | N11: #N/A | O11: #N/A | P11: #N/A | Q11: #N/A | R11: #N/A | S11: #N/A
D12: 2000 | E12: 7 | F12: Denmark | G12: 16.2495 | H12: 61.2491 | J12: #N/A | K12: #N/A | L12: -73.756871 | M12: #N/A | N12: #N/A | O12: #N/A | P12: #N/A | Q12: #N/A | R12: #N/A | S12: #N/A
D13: 2000 | E13: 8 | F13: Denmark | G13: 16.25 | H13: 61.25 | J13: #N/A | K13: #N/A | L13: -48.626973 | M13: #N/A | N13: #N/A | O13: #N/A | P13: #N/A | Q13: #N/A | R13: #N/A | S13: #N/A
D14: 2000 | E14: 9 | F14: Denmark | G14: 13.504 | H14: 56.3072 | J14: #N/A | K14: #N/A | L14: 80.354304 | M14: #N/A | N14: #N/A | O14: #N/A | P14: #N/A | Q14: #N/A | R14: #N/A | S14: #N/A
D15: 2000 | E15: 10 | F15: Denmark | G15: 11.091 | H15: 51.9638 | J15: #N/A | K15: #N/A | L15: 30.229289 | M15: #N/A | N15: #N/A | O15: #N/A | P15: #N/A | Q15: #N/A | R15: #N/A | S15: #N/A
D16: 2000 | E16: 11 | F16: Denmark | G16: 6.9995 | H16: 44.5991 | J16: #N/A | K16: #N/A | L16: 36.781526 | M16: #N/A | N16: #N/A | O16: #N/A | P16: #N/A | Q16: #N/A | R16: #N/A | S16: #N/A
D17: 2000 | E17: 12 | F17: Denmark | G17: 3.5975 | H17: 38.4755 | J17: #N/A | K17: #N/A | L17: 12.796508 | M17: #N/A | N17: #N/A | O17: #N/A | P17: #N/A | Q17: #N/A | R17: #N/A | S17: #N/A
D18: 2001 | E18: 1 | F18: Denmark | G18: 1.7405 | H18: 35.1329 | J18: #N/A | K18: #N/A | L18: 14.4 | M18: #N/A | N18: #N/A | O18: #N/A | P18: #N/A | Q18: #N/A | R18: #N/A | S18: #N/A
... D110: 2008 | E110: 9 | F110: Denmark | G110: 13.568 | H110: 56.4224 | J110: #N/A | K110: #N/A | L110: -12.692155 | M110: #N/A | N110: #N/A | O110: #N/A | P110: #N/A | Q110: #N/A | R110: #N/A | S110: #N/A
D111: 2008 | E111: 10 | F111: Denmark | G111: 9.7065 | H111: 49.4717 | O111: Canada | P111: 35.06965 | Q111: 11
D112: 2008 | E112: 11 | F112: Denmark | G112: 5.6575 | H112: 42.1835 | O112: Canada | P112: 18.39913 | Q112: 12
D113: 2008 | E113: 12 | F113: Denmark | G113: 2.31 | H113: 36.158 | O113: Canada | P113: 12.68168 | Q113: 1
D114: 2009 | E114: 1 | F114: Denmark | G114: 0.8495 | H114: 33.5291 | O114: Canada | P114: 20.15161 | Q114: 2
D115: 2009 | E115: 2 | F115: Denmark | G115: 0.5275 | H115: 32.9495 | O115: Canada | P115: 27.57747 | Q115: 3
D116: 2009 | E116: 3 | F116: Denmark | G116: 3.949 | H116: 39.1082 | O116: Canada | P116: 41.76824 | Q116: 4
D117: 2009 | E117: 4 | F117: Denmark | G117: 9.5085 | H117: 49.1153 | O117: Canada | P117: 51.28369 | Q117: 5
D118: 2009 | E118: 5 | F118: Denmark | G118: 12.4455 | H118: 54.4019 | O118: Canada | P118: 59.81216 | Q118: 6
D119: 2009 | E119: 6 | F119: Denmark | G119: 15.158 | H119: 59.2844 | O119: Canada | P119: 63.46105 | Q119: 7
D120: 2009 | E120: 7 | F120: Denmark | G120: 18.4115 | H120: 65.1407 | O120: Canada | P120: 64.57251 | Q120: 8
D121: 2009 | E121: 8 | F121: Denmark | G121: 18.0555 | H121: 64.4999 | O121: Canada | P121: 58.62344 | Q121: 9
D122: 2009 | E122: 9 | F122: Denmark | G122: 14.7685 | H122: 58.5833 | O122: Canada | P122: 42.39385 | Q122: 10
... D169: 2013 | E169: 8 | F169: Denmark | G169: 17.745 | H169: 63.941 | O169: Canada | P169: 58.48383 | Q169: 9
D170: 2000 | E170: 2 | F170: Turkey | G170: 2.9882353 | H170: 37.378824
D171: 2000 | E171: 3 | F171: Turkey | G171: 6.0615098 | H171: 42.910718
D172: 2000 | E172: 4 | F172: Turkey | G172: 13.528667 | H172: 56.3516
D173: 2000 | E173: 5 | F173: Turkey | G173: 16.585451 | H173: 61.853812
D174: 2000 | E174: 6 | F174: Turkey | G174: 21.348471 | H174: 70.427247
D175: 2000 | E175: 7 | F175: Turkey | G175: 26.047745 | H175: 78.885941
D176: 2000 | E176: 8 | F176: Turkey | G176: 24.407373 | H176: 75.933271
D177: 2000 | E177: 9 | F177: Turkey | G177: 20.620627 | H177: 69.117129
D178: 2000 | E178: 10 | F178: Turkey | G178: 14.320804 | H178: 57.777447
D179: 2000 | E179: 11 | F179: Turkey | G179: 10.619882 | H179: 51.115788
...

Sheet Sheet4
A2: Row Labels | B2: Average of AvgTemp (C)
A3: 2000 | B3: 13.165428
A4: 2001 | B4: 12.271553
A5: 2002 | B5: 12.346151
A6: 2003 | B6: 12.085654
A7: 2004 | B7: 12.182721
A8: 2005 | B8: 12.176344
A9: 2006 | B9: 12.451176
A10: 2007 | B10: 12.509966
A11: 2008 | B11: 12.330021
A12: 2009 | B12: 12.17716
A13: 2010 | B13: 12.207771
A14: 2011 | B14: 12.118174
... A16: 2013 | B16: 13.030905
A17: Grand Total | B17: 12.350753

Sheet Sheet5
A2: Row Labels | B2: Average of AvgTemp (C)
A3: 2000 | B3: 15.826648
A4: 2001 | B4: 15.17129
A5: 2002 | B5: 15.141981
A6: 2003 | B6: 14.968209
A7: 2004 | B7: 14.980913
A8: 2005 | B8: 15.162541
A9: 2006 | B9: 15.492709
A10: 2007 | B10: 15.19268
A11: 2008 | B11: 14.854569
A12: 2009 | B12: 14.803492
A13: 2010 | B13: 14.883878
A14: 2011 | B14: 15.101007
... A16: 2013 | B16: 16.384296
A17: Grand Total | B17: 15.256721

Sheet Cost
A1: Parameter | B1: Value | C1: Notes
A2: StockoutCostPerUnit | B2: 15 | C2: Assumed margin lost per unit of unmet demand
A3: HoldingCostPerUnit | B3: 3 | C3: Assumed markdown / carrying cost per unit of overstock
A4: BufferPct | B4: =LookupTables!$I$6 | C4: Decision variable (mirrors LookupTables!I6)
A5: TotalCost | B5: =SUMPRODUCT(Solver!N2:N105,$B$2)+SUMPRODUCT(Solver!O2:O105,$B$3) | C5: Objective: lost sales x stockout cost + excess inventory x holding cost
A7: SOLVER CONFIGURATION
A8: Set Objective: Cost!$B$5 (TotalCost)
A9: To: Min
A10: By Changing: LookupTables!$I$6 (InvBufferPct)
A11: Constraints: LookupTables!$I$6 >= 0 ; LookupTables!$I$6 <= 0.5
A12: Method: GRG Nonlinear
A14: Caveat: Noise (col H) and Inventory (col L) use volatile RAND(), so Solver
A15: optimizes against a single redrawn sample each time it runs. Freeze columns H
A16: and L (Copy > Paste Special > Values Only) before solving for a stable answer.
A18: Added for the portfolio writeup. Not part of the original submitted workbook,
A19: which described this Solver setup on FormulaReference but never implemented it.
